Workbook

Sheet #README
A1: #sheet | B1: #scenario | C1: #expected
A2: comment | B2: comment | C2: comment
A3: NoKey | B3: 无 key，大量行 | C3: 正常
A4: SingleKey | B4: 单 key | C4: 正常
A5: MultiKey | B5: 多 key/复合 key | C5: 正常
A6: WideData | B6: 超多列 100 x 300 行 | C6: 正常
A7: HugeRows | B7: 超多行 10000 x 12 列 | C7: 正常
A8: ComplexTypes | B8: 复杂类型、Unicode、极值 | C8: 正常
A9: FormulaCells | B9: 公式、错误公式、跨表公式 | C9: 检验公式求值
A10: CommentRows | B10: 数据区 # 注释行 | C10: 注释行被跳过
A11: CommentCols | B11: 表头 # 注释列 | C11: 注释列被跳过
A12: CommentSheet | B12: 全 # 注释表 | C12: 整表无有效字段而跳过
... A23: NullableTypes | B23: Nullable 类型 | C23: 空单元格转换为 null；零值与非空值正常转换

Sheet NoKey
A1: id | B1: name | C1: enabled | D1: score | E1: createdAt | F1: tags | G1: position | H1: metadata
A2: int | B2: string | C2: bool | D2: double | E2: DateTime | F2: List<int> | G2: Vector3 | H2: Dictionary<string, int>
A3: 编号 | B3: 名称：包含中文与 Unicode | C3: 是否启用 | D3: 分数 | E3: 创建时间 | F3: JSON 整数列表 | G3: Unity 三维向量 | H3: JSON 字典
A4: 100 | B4: 行1_列1_中文_Unicode_😀_comma,quote"_line | C4: FALSE | D4: 1.28 | E4: 46236.503 | F4: [1,2,3,1] | G4: {"x":1,"y":2,"z":3} | H4: {"alpha":1,"row":1}
A5: 200 | B5: 行2_列1_中文_Unicode_😀_comma,quote"_line | C5: TRUE | D5: 2.53 | E5: 46237.503 | F5: [1,2,3,2] | G5: {"x":2,"y":3,"z":4} | H5: {"alpha":1,"row":2}
A6: 300 | B6: 行3_列1_中文_Unicode_😀_comma,quote"_line | C6: FALSE | D6: 3.78 | E6: 46238.503 | F6: [1,2,3,3] | G6: {"x":3,"y":4,"z":5} | H6: {"alpha":1,"row":3}
A7: 400 | B7: 行4_列1_中文_Unicode_😀_comma,quote"_line | C7: TRUE | D7: 5.03 | E7: 46239.503 | F7: [1,2,3,4] | G7: {"x":4,"y":5,"z":6} | H7: {"alpha":1,"row":4}
A8: 500 | B8: 行5_列1_中文_Unicode_😀_comma,quote"_line | C8: FALSE | D8: 6.28 | E8: 46240.503 | F8: [1,2,3,5] | G8: {"x":5,"y":6,"z":7} | H8: {"alpha":1,"row":5}
A9: 600 | B9: 行6_列1_中文_Unicode_😀_comma,quote"_line | C9: TRUE | D9: 7.53 | E9: 46241.503 | F9: [1,2,3,6] | G9: {"x":6,"y":7,"z":8} | H9: {"alpha":1,"row":6}
A10: 700 | B10: 行7_列1_中文_Unicode_😀_comma,quote"_line | C10: FALSE | D10: 8.78 | E10: 46242.503 | F10: [1,2,3,7] | G10: {"x":7,"y":8,"z":9} | H10: {"alpha":1,"row":7}
A11: 800 | B11: 行8_列1_中文_Unicode_😀_comma,quote"_line | C11: TRUE | D11: 10.03 | E11: 46243.503 | F11: [1,2,3,8] | G11: {"x":8,"y":9,"z":10} | H11: {"alpha":1,"row":8}
A12: 900 | B12: 行9_列1_中文_Unicode_😀_comma,quote"_line | C12: FALSE | D12: 11.28 | E12: 46244.503 | F12: [1,2,3,9] | G12: {"x":9,"y":10,"z":11} | H12: {"alpha":1,"row":9}
A13: 1000 | B13: 行10_列1_中文_Unicode_😀_comma,quote"_line | C13: TRUE | D13: 12.53 | E13: 46245.503 | F13: [1,2,3,10] | G13: {"x":10,"y":11,"z":12} | H13: {"alpha":1,"row":10}
A14: 1100 | B14: 行11_列1_中文_Unicode_😀_comma,quote"_line | C14: FALSE | D14: 13.78 | E14: 46246.503 | F14: [1,2,3,11] | G14: {"x":11,"y":12,"z":13} | H14: {"alpha":1,"row":11}
A15: 1200 | B15: 行12_列1_中文_Unicode_😀_comma,quote"_line | C15: TRUE | D15: 15.03 | E15: 46247.503 | F15: [1,2,3,12] | G15: {"x":12,"y":13,"z":14} | H15: {"alpha":1,"row":12}
... A2003: 200000 | B2003: 行2000_列1_中文_Unicode_😀_comma,quote"_line | C2003: TRUE | D2003: 2500.03 | E2003: 46247.503 | F2003: [1,2,3,2000] | G2003: {"x":2000,"y":2001,"z":2002} | H2003: {"alpha":1,"row":2000}

Sheet SingleKey
A1: id,key | B1: name | C1: enabled | D1: score | E1: createdAt | F1: tags | G1: position | H1: metadata
A2: int | B2: string | C2: bool | D2: double | E2: DateTime | F2: List<int> | G2: Vector3 | H2: Dictionary<string, int>
A3: 编号 | B3: 名称：包含中文与 Unicode | C3: 是否启用 | D3: 分数 | E3: 创建时间 | F3: JSON 整数列表 | G3: Unity 三维向量 | H3: JSON 字典
A4: 100 | B4: 行1_列1_中文_Unicode_😀_comma,quote"_line | C4: FALSE | D4: 1.28 | E4: 46236.503 | F4: [1,2,3,1] | G4: {"x":1,"y":2,"z":3} | H4: {"alpha":1,"row":1}
A5: 200 | B5: 行2_列1_中文_Unicode_😀_comma,quote"_line | C5: TRUE | D5: 2.53 | E5: 46237.503 | F5: [1,2,3,2] | G5: {"x":2,"y":3,"z":4} | H5: {"alpha":1,"row":2}
A6: 300 | B6: 行3_列1_中文_Unicode_😀_comma,quote"_line | C6: FALSE | D6: 3.78 | E6: 46238.503 | F6: [1,2,3,3] | G6: {"x":3,"y":4,"z":5} | H6: {"alpha":1,"row":3}
A7: 400 | B7: 行4_列1_中文_Unicode_😀_comma,quote"_line | C7: TRUE | D7: 5.03 | E7: 46239.503 | F7: [1,2,3,4] | G7: {"x":4,"y":5,"z":6} | H7: {"alpha":1,"row":4}
A8: 500 | B8: 行5_列1_中文_Unicode_😀_comma,quote"_line | C8: FALSE | D8: 6.28 | E8: 46240.503 | F8: [1,2,3,5] | G8: {"x":5,"y":6,"z":7} | H8: {"alpha":1,"row":5}
A9: 600 | B9: 行6_列1_中文_Unicode_😀_comma,quote"_line | C9: TRUE | D9: 7.53 | E9: 46241.503 | F9: [1,2,3,6] | G9: {"x":6,"y":7,"z":8} | H9: {"alpha":1,"row":6}
A10: 700 | B10: 行7_列1_中文_Unicode_😀_comma,quote"_line | C10: FALSE | D10: 8.78 | E10: 46242.503 | F10: [1,2,3,7] | G10: {"x":7,"y":8,"z":9} | H10: {"alpha":1,"row":7}
A11: 800 | B11: 行8_列1_中文_Unicode_😀_comma,quote"_line | C11: TRUE | D11: 10.03 | E11: 46243.503 | F11: [1,2,3,8] | G11: {"x":8,"y":9,"z":10} | H11: {"alpha":1,"row":8}
A12: 900 | B12: 行9_列1_中文_Unicode_😀_comma,quote"_line | C12: FALSE | D12: 11.28 | E12: 46244.503 | F12: [1,2,3,9] | G12: {"x":9,"y":10,"z":11} | H12: {"alpha":1,"row":9}
A13: 1000 | B13: 行10_列1_中文_Unicode_😀_comma,quote"_line | C13: TRUE | D13: 12.53 | E13: 46245.503 | F13: [1,2,3,10] | G13: {"x":10,"y":11,"z":12} | H13: {"alpha":1,"row":10}
A14: 1100 | B14: 行11_列1_中文_Unicode_😀_comma,quote"_line | C14: FALSE | D14: 13.78 | E14: 46246.503 | F14: [1,2,3,11] | G14: {"x":11,"y":12,"z":13} | H14: {"alpha":1,"row":11}
A15: 1200 | B15: 行12_列1_中文_Unicode_😀_comma,quote"_line | C15: TRUE | D15: 15.03 | E15: 46247.503 | F15: [1,2,3,12] | G15: {"x":12,"y":13,"z":14} | H15: {"alpha":1,"row":12}
... A3003: 300000 | B3003: 行3000_列1_中文_Unicode_😀_comma,quote"_line | C3003: TRUE | D3003: 3750.03 | E3003: 46239.503 | F3003: [1,2,3,3000] | G3003: {"x":3000,"y":3001,"z":3002} | H3003: {"alpha":1,"row":3000}

Sheet MultiKey
A1: id,key | B1: name,key | C1: enabled | D1: score | E1: createdAt | F1: tags | G1: position | H1: metadata
A2: int | B2: string | C2: bool | D2: double | E2: DateTime | F2: List<int> | G2: Vector3 | H2: Dictionary<string, int>
A3: 编号 | B3: 名称：包含中文与 Unicode | C3: 是否启用 | D3: 分数 | E3: 创建时间 | F3: JSON 整数列表 | G3: Unity 三维向量 | H3: JSON 字典
A4: 100 | B4: 行1_列1_中文_Unicode_😀_comma,quote"_line | C4: FALSE | D4: 1.28 | E4: 46236.503 | F4: [1,2,3,1] | G4: {"x":1,"y":2,"z":3} | H4: {"alpha":1,"row":1}
A5: 200 | B5: 行2_列1_中文_Unicode_😀_comma,quote"_line | C5: TRUE | D5: 2.53 | E5: 46237.503 | F5: [1,2,3,2] | G5: {"x":2,"y":3,"z":4} | H5: {"alpha":1,"row":2}
A6: 300 | B6: 行3_列1_中文_Unicode_😀_comma,quote"_line | C6: FALSE | D6: 3.78 | E6: 46238.503 | F6: [1,2,3,3] | G6: {"x":3,"y":4,"z":5} | H6: {"alpha":1,"row":3}
A7: 400 | B7: 行4_列1_中文_Unicode_😀_comma,quote"_line | C7: TRUE | D7: 5.03 | E7: 46239.503 | F7: [1,2,3,4] | G7: {"x":4,"y":5,"z":6} | H7: {"alpha":1,"row":4}
A8: 500 | B8: 行5_列1_中文_Unicode_😀_comma,quote"_line | C8: FALSE | D8: 6.28 | E8: 46240.503 | F8: [1,2,3,5] | G8: {"x":5,"y":6,"z":7} | H8: {"alpha":1,"row":5}
A9: 600 | B9: 行6_列1_中文_Unicode_😀_comma,quote"_line | C9: TRUE | D9: 7.53 | E9: 46241.503 | F9: [1,2,3,6] | G9: {"x":6,"y":7,"z":8} | H9: {"alpha":1,"row":6}
A10: 700 | B10: 行7_列1_中文_Unicode_😀_comma,quote"_line | C10: FALSE | D10: 8.78 | E10: 46242.503 | F10: [1,2,3,7] | G10: {"x":7,"y":8,"z":9} | H10: {"alpha":1,"row":7}
A11: 800 | B11: 行8_列1_中文_Unicode_😀_comma,quote"_line | C11: TRUE | D11: 10.03 | E11: 46243.503 | F11: [1,2,3,8] | G11: {"x":8,"y":9,"z":10} | H11: {"alpha":1,"row":8}
A12: 900 | B12: 行9_列1_中文_Unicode_😀_comma,quote"_line | C12: FALSE | D12: 11.28 | E12: 46244.503 | F12: [1,2,3,9] | G12: {"x":9,"y":10,"z":11} | H12: {"alpha":1,"row":9}
A13: 1000 | B13: 行10_列1_中文_Unicode_😀_comma,quote"_line | C13: TRUE | D13: 12.53 | E13: 46245.503 | F13: [1,2,3,10] | G13: {"x":10,"y":11,"z":12} | H13: {"alpha":1,"row":10}
A14: 1100 | B14: 行11_列1_中文_Unicode_😀_comma,quote"_line | C14: FALSE | D14: 13.78 | E14: 46246.503 | F14: [1,2,3,11] | G14: {"x":11,"y":12,"z":13} | H14: {"alpha":1,"row":11}
A15: 1200 | B15: 行12_列1_中文_Unicode_😀_comma,quote"_line | C15: TRUE | D15: 15.03 | E15: 46247.503 | F15: [1,2,3,12] | G15: {"x":12,"y":13,"z":14} | H15: {"alpha":1,"row":12}
... A2503: 250000 | B2503: 行2500_列1_中文_Unicode_😀_comma,quote"_line | C2503: TRUE | D2503: 3125.03 | E2503: 46243.503 | F2503: [1,2,3,2500] | G2503: {"x":2500,"y":2501,"z":2502} | H2503: {"alpha":1,"row":2500}

Sheet WideData
A1: field001,key | B1: field002 | C1: field003 | D1: field004 | E1: field005 | F1: field006 | G1: field007 | H1: field008 | I1: field009 | J1: field010 | K1: field011 | L1: field012 | M1: field013 | N1: field014 | O1: field015 | P1: field016 | Q1: field017 | R1: field018 | S1: field019 | T1: field020 | U1: field021 | V1: field022 | W1: field023 | X1: field024 | Y1: field025 | Z1: field026 | AA1: field027 | AB1: field028 | AC1: field029 | AD1: field030 | AE1: field031 | AF1: field032 | AG1: field033 | AH1: field034 | AI1: field035 | AJ1: field036 | AK1: field037 | AL1: field038 | AM1: field039 | AN1: field040 | AO1: field041 | AP1: field042 | AQ1: field043 | AR1: field044 | AS1: field045 | AT1: field046 | AU1: field047 | AV1: field048 | AW1: field049 | AX1: field050 | AY1: field051 | AZ1: field052 | BA1: field053 | BB1: field054 | BC1: field055 | BD1: field056 | BE1: field057 | BF1: field058 | BG1: field059 | BH1: field060 | BI1: field061 | BJ1: field062 | BK1: field063 | BL1: field064 | BM1: field065 | BN1: field066 | BO1: field067 | BP1: field068 | BQ1: field069 | BR1: field070 | BS1: field071 | BT1: field072 | BU1: field073 | BV1: field074 | BW1: field075 | BX1: field076 | BY1: field077 | BZ1: field078 | CA1: field079 | CB1: field080 | CC1: field081 | CD1: field082 | CE1: field083 | CF1: field084 | CG1: field085 | CH1: field086 | CI1: field087 | CJ1: field088 | CK1: field089 | CL1: field090 | CM1: field091 | CN1: field092 | CO1: field093 | CP1: field094 | CQ1: field095 | CR1: field096 | CS1: field097 | CT1: field098 | CU1: field099 | CV1: field100
A2: string | B2: bool | C2: double | D2: List<int> | E2: int | F2: string | G2: bool | H2: double | I2: List<int> | J2: int | K2: string | L2: bool | M2: double | N2: List<int> | O2: int | P2: string | Q2: bool | R2: double | S2: List<int> | T2: int | U2: string | V2: bool | W2: double | X2: List<int> | Y2: int | Z2: string | AA2: bool | AB2: double | AC2: List<int> | AD2: int | AE2: string | AF2: bool | AG2: double | AH2: List<int> | AI2: int | AJ2: string | AK2: bool | AL2: double | AM2: List<int> | AN2: int | AO2: string | AP2: bool | AQ2: double | AR2: List<int> | AS2: int | AT2: string | AU2: bool | AV2: double | AW2: List<int> | AX2: int | AY2: string | AZ2: bool | BA2: double | BB2: List<int> | BC2: int | BD2: string | BE2: bool | BF2: double | BG2: List<int> | BH2: int | BI2: string | BJ2: bool | BK2: double | BL2: List<int> | BM2: int | BN2: string | BO2: bool | BP2: double | BQ2: List<int> | BR2: int | BS2: string | BT2: bool | BU2: double | BV2: List<int> | BW2: int | BX2: string | BY2: bool | BZ2: double | CA2: List<int> | CB2: int | CC2: string | CD2: bool | CE2: double | CF2: List<int> | CG2: int | CH2: string | CI2: bool | CJ2: double | CK2: List<int> | CL2: int | CM2: string | CN2: bool | CO2: double | CP2: List<int> | CQ2: int | CR2: string | CS2: bool | CT2: double | CU2: List<int> | CV2: int
A3: 宽表字段 1 第二行备注：<>&"' | B3: 宽表字段 2 第二行备注：<>&"' | C3: 宽表字段 3 第二行备注：<>&"' | D3: 宽表字段 4 第二行备注：<>&"' | E3: 宽表字段 5 第二行备注：<>&"' | F3: 宽表字段 6 第二行备注：<>&"' | G3: 宽表字段 7 第二行备注：<>&"' | H3: 宽表字段 8 第二行备注：<>&"' | I3: 宽表字段 9 第二行备注：<>&"' | J3: 宽表字段 10 第二行备注：<>&"' | K3: 宽表字段 11 第二行备注：<>&"' | L3: 宽表字段 12 第二行备注：<>&"' | M3: 宽表字段 13 第二行备注：<>&"' | N3: 宽表字段 14 第二行备注：<>&"' | O3: 宽表字段 15 第二行备注：<>&"' | P3: 宽表字段 16 第二行备注：<>&"' | Q3: 宽表字段 17 第二行备注：<>&"' | R3: 宽表字段 18 第二行备注：<>&"' | S3: 宽表字段 19 第二行备注：<>&"' | T3: 宽表字段 20 第二行备注：<>&"' | U3: 宽表字段 21 第二行备注：<>&"' | V3: 宽表字段 22 第二行备注：<>&"' | W3: 宽表字段 23 第二行备注：<>&"' | X3: 宽表字段 24 第二行备注：<>&"' | Y3: 宽表字段 25 第二行备注：<>&"' | Z3: 宽表字段 26 第二行备注：<>&"' | AA3: 宽表字段 27 第二行备注：<>&"' | AB3: 宽表字段 28 第二行备注：<>&"' | AC3: 宽表字段 29 第二行备注：<>&"' | AD3: 宽表字段 30 第二行备注：<>&"' | AE3: 宽表字段 31 第二行备注：<>&"' | AF3: 宽表字段 32 第二行备注：<>&"' | AG3: 宽表字段 33 第二行备注：<>&"' | AH3: 宽表字段 34 第二行备注：<>&"' | AI3: 宽表字段 35 第二行备注：<>&"' | AJ3: 宽表字段 36 第二行备注：<>&"' | AK3: 宽表字段 37 第二行备注：<>&"' | AL3: 宽表字段 38 第二行备注：<>&"' | AM3: 宽表字段 39 第二行备注：<>&"' | AN3: 宽表字段 40 第二行备注：<>&"' | AO3: 宽表字段 41 第二行备注：<>&"' | AP3: 宽表字段 42 第二行备注：<>&"' | AQ3: 宽表字段 43 第二行备注：<>&"' | AR3: 宽表字段 44 第二行备注：<>&"' | AS3: 宽表字段 45 第二行备注：<>&"' | AT3: 宽表字段 46 第二行备注：<>&"' | AU3: 宽表字段 47 第二行备注：<>&"' | AV3: 宽表字段 48 第二行备注：<>&"' | AW3: 宽表字段 49 第二行备注：<>&"' | AX3: 宽表字段 50 第二行备注：<>&"' | AY3: 宽表字段 51 第二行备注：<>&"' | AZ3: 宽表字段 52 第二行备注：<>&"' | BA3: 宽表字段 53 第二行备注：<>&"' | BB3: 宽表字段 54 第二行备注：<>&"' | BC3: 宽表字段 55 第二行备注：<>&"' | BD3: 宽表字段 56 第二行备注：<>&"' | BE3: 宽表字段 57 第二行备注：<>&"' | BF3: 宽表字段 58 第二行备注：<>&"' | BG3: 宽表字段 59 第二行备注：<>&"' | BH3: 宽表字段 60 第二行备注：<>&"' | BI3: 宽表字段 61 第二行备注：<>&"' | BJ3: 宽表字段 62 第二行备注：<>&"' | BK3: 宽表字段 63 第二行备注：<>&"' | BL3: 宽表字段 64 第二行备注：<>&"' | BM3: 宽表字段 65 第二行备注：<>&"' | BN3: 宽表字段 66 第二行备注：<>&"' | BO3: 宽表字段 67 第二行备注：<>&"' | BP3: 宽表字段 68 第二行备注：<>&"' | BQ3: 宽表字段 69 第二行备注：<>&"' | BR3: 宽表字段 70 第二行备注：<>&"' | BS3: 宽表字段 71 第二行备注：<>&"' | BT3: 宽表字段 72 第二行备注：<>&"' | BU3: 宽表字段 73 第二行备注：<>&"' | BV3: 宽表字段 74 第二行备注：<>&"' | BW3: 宽表字段 75 第二行备注：<>&"' | BX3: 宽表字段 76 第二行备注：<>&"' | BY3: 宽表字段 77 第二行备注：<>&"' | BZ3: 宽表字段 78 第二行备注：<>&"' | CA3: 宽表字段 79 第二行备注：<>&"' | CB3: 宽表字段 80 第二行备注：<>&"' | CC3: 宽表字段 81 第二行备注：<>&"' | CD3: 宽表字段 82 第二行备注：<>&"' | CE3: 宽表字段 83 第二行备注：<>&"' | CF3: 宽表字段 84 第二行备注：<>&"' | CG3: 宽表字段 85 第二行备注：<>&"' | CH3: 宽表字段 86 第二行备注：<>&"' | CI3: 宽表字段 87 第二行备注：<>&"' | CJ3: 宽表字段 88 第二行备注：<>&"' | CK3: 宽表字段 89 第二行备注：<>&"' | CL3: 宽表字段 90 第二行备注：<>&"' | CM3: 宽表字段 91 第二行备注：<>&"' | CN3: 宽表字段 92 第二行备注：<>&"' | CO3: 宽表字段 93 第二行备注：<>&"' | CP3: 宽表字段 94 第二行备注：<>&"' | CQ3: 宽表字段 95 第二行备注：<>&"' | CR3: 宽表字段 96 第二行备注：<>&"' | CS3: 宽表字段 97 第二行备注：<>&"' | CT3: 宽表字段 98 第二行备注：<>&"' | CU3: 宽表字段 99 第二行备注：<>&"' | CV3: 宽表字段 100 第二行备注：<>&"'
A4: 行1_列0_中文_Unicode_😀_comma,quote"_line | B4: TRUE | C4: 1.27 | D4: [1,2,3,1] | E4: 104 | F4: 行1_列5_中文_Unicode_😀_comma,quote"_line | G4: FALSE | H4: 1.32 | I4: [1,2,3,1] | J4: 109 | K4: 行1_列10_中文_Unicode_😀_comma,quote"_line | L4: TRUE | M4: 1.37 | N4: [1,2,3,1] | O4: 114 | P4: 行1_列15_中文_Unicode_😀_comma,quote"_line | Q4: FALSE | R4: 1.42 | S4: [1,2,3,1] | T4: 119 | U4: 行1_列20_中文_Unicode_😀_comma,quote"_line | V4: TRUE | W4: 1.47 | X4: [1,2,3,1] | Y4: 124 | Z4: 行1_列25_中文_Unicode_😀_comma,quote"_line | AA4: FALSE | AB4: 1.52 | AC4: [1,2,3,1] | AD4: 129 | AE4: 行1_列30_中文_Unicode_😀_comma,quote"_line | AF4: TRUE | AG4: 1.57 | AH4: [1,2,3,1] | AI4: 134 | AJ4: 行1_列35_中文_Unicode_😀_comma,quote"_line | AK4: FALSE | AL4: 1.62 | AM4: [1,2,3,1] | AN4: 139 | AO4: 行1_列40_中文_Unicode_😀_comma,quote"_line | AP4: TRUE | AQ4: 1.67 | AR4: [1,2,3,1] | AS4: 144 | AT4: 行1_列45_中文_Unicode_😀_comma,quote"_line | AU4: FALSE | AV4: 1.72 | AW4: [1,2,3,1] | AX4: 149 | AY4: 行1_列50_中文_Unicode_😀_comma,quote"_line | AZ4: TRUE | BA4: 1.77 | BB4: [1,2,3,1] | BC4: 154 | BD4: 行1_列55_中文_Unicode_😀_comma,quote"_line | BE4: FALSE | BF4: 1.82 | BG4: [1,2,3,1] | BH4: 159 | BI4: 行1_列60_中文_Unicode_😀_comma,quote"_line | BJ4: TRUE | BK4: 1.87 | BL4: [1,2,3,1] | BM4: 164 | BN4: 行1_列65_中文_Unicode_😀_comma,quote"_line | BO4: FALSE | BP4: 1.92 | BQ4: [1,2,3,1] | BR4: 169 | BS4: 行1_列70_中文_Unicode_😀_comma,quote"_line | BT4: TRUE | BU4: 1.97 | BV4: [1,2,3,1] | BW4: 174 | BX4: 行1_列75_中文_Unicode_😀_comma,quote"_line | BY4: FALSE | BZ4: 2.02 | CA4: [1,2,3,1] | CB4: 179 | CC4: 行1_列80_中文_Unicode_😀_comma,quote"_line | CD4: TRUE | CE4: 2.07 | CF4: [1,2,3,1] | CG4: 184 | CH4: 行1_列85_中文_Unicode_😀_comma,quote"_line | CI4: FALSE | CJ4: 2.12 | CK4: [1,2,3,1] | CL4: 189 | CM4: 行1_列90_中文_Unicode_😀_comma,quote"_line | CN4: TRUE | CO4: 2.17 | CP4: [1,2,3,1] | CQ4: 194 | CR4: 行1_列95_中文_Unicode_😀_comma,quote"_line | CS4: FALSE | CT4: 2.22 | CU4: [1,2,3,1] | CV4: 199
A5: 行2_列0_中文_Unicode_😀_comma,quote"_line | B5: FALSE | C5: 2.52 | D5: [1,2,3,2] | E5: 204 | F5: 行2_列5_中文_Unicode_😀_comma,quote"_line | G5: TRUE | H5: 2.57 | I5: [1,2,3,2] | J5: 209 | K5: 行2_列10_中文_Unicode_😀_comma,quote"_line | L5: FALSE | M5: 2.62 | N5: [1,2,3,2] | O5: 214 | P5: 行2_列15_中文_Unicode_😀_comma,quote"_line | Q5: TRUE | R5: 2.67 | S5: [1,2,3,2] | T5: 219 | U5: 行2_列20_中文_Unicode_😀_comma,quote"_line | V5: FALSE | W5: 2.72 | X5: [1,2,3,2] | Y5: 224 | Z5: 行2_列25_中文_Unicode_😀_comma,quote"_line | AA5: TRUE | AB5: 2.77 | AC5: [1,2,3,2] | AD5: 229 | AE5: 行2_列30_中文_Unicode_😀_comma,quote"_line | AF5: FALSE | AG5: 2.82 | AH5: [1,2,3,2] | AI5: 234 | AJ5: 行2_列35_中文_Unicode_😀_comma,quote"_line | AK5: TRUE | AL5: 2.87 | AM5: [1,2,3,2] | AN5: 239 | AO5: 行2_列40_中文_Unicode_😀_comma,quote"_line | AP5: FALSE | AQ5: 2.92 | AR5: [1,2,3,2] | AS5: 244 | AT5: 行2_列45_中文_Unicode_😀_comma,quote"_line | AU5: TRUE | AV5: 2.97 | AW5: [1,2,3,2] | AX5: 249 | AY5: 行2_列50_中文_Unicode_😀_comma,quote"_line | AZ5: FALSE | BA5: 3.02 | BB5: [1,2,3,2] | BC5: 254 | BD5: 行2_列55_中文_Unicode_😀_comma,quote"_line | BE5: TRUE | BF5: 3.07 | BG5: [1,2,3,2] | BH5: 259 | BI5: 行2_列60_中文_Unicode_😀_comma,quote"_line | BJ5: FALSE | BK5: 3.12 | BL5: [1,2,3,2] | BM5: 264 | BN5: 行2_列65_中文_Unicode_😀_comma,quote"_line | BO5: TRUE | BP5: 3.17 | BQ5: [1,2,3,2] | BR5: 269 | BS5: 行2_列70_中文_Unicode_😀_comma,quote"_line | BT5: FALSE | BU5: 3.22 | BV5: [1,2,3,2] | BW5: 274 | BX5: 行2_列75_中文_Unicode_😀_comma,quote"_line | BY5: TRUE | BZ5: 3.27 | CA5: [1,2,3,2] | CB5: 279 | CC5: 行2_列80_中文_Unicode_😀_comma,quote"_line | CD5: FALSE | CE5: 3.32 | CF5: [1,2,3,2] | CG5: 284 | CH5: 行2_列85_中文_Unicode_😀_comma,quote"_line | CI5: TRUE | CJ5: 3.37 | CK5: [1,2,3,2] | CL5: 289 | CM5: 行2_列90_中文_Unicode_😀_comma,quote"_line | CN5: FALSE | CO5: 3.42 | CP5: [1,2,3,2] | CQ5: 294 | CR5: 行2_列95_中文_Unicode_😀_comma,quote"_line | CS5: TRUE | CT5: 3.47 | CU5: [1,2,3,2] | CV5: 299
A6: 行3_列0_中文_Unicode_😀_comma,quote"_line | B6: TRUE | C6: 3.77 | D6: [1,2,3,3] | E6: 304 | F6: 行3_列5_中文_Unicode_😀_comma,quote"_line | G6: FALSE | H6: 3.82 | I6: [1,2,3,3] | J6: 309 | K6: 行3_列10_中文_Unicode_😀_comma,quote"_line | L6: TRUE | M6: 3.87 | N6: [1,2,3,3] | O6: 314 | P6: 行3_列15_中文_Unicode_😀_comma,quote"_line | Q6: FALSE | R6: 3.92 | S6: [1,2,3,3] | T6: 319 | U6: 行3_列20_中文_Unicode_😀_comma,quote"_line | V6: TRUE | W6: 3.97 | X6: [1,2,3,3] | Y6: 324 | Z6: 行3_列25_中文_Unicode_😀_comma,quote"_line | AA6: FALSE | AB6: 4.02 | AC6: [1,2,3,3] | AD6: 329 | AE6: 行3_列30_中文_Unicode_😀_comma,quote"_line | AF6: TRUE | AG6: 4.07 | AH6: [1,2,3,3] | AI6: 334 | AJ6: 行3_列35_中文_Unicode_😀_comma,quote"_line | AK6: FALSE | AL6: 4.12 | AM6: [1,2,3,3] | AN6: 339 | AO6: 行3_列40_中文_Unicode_😀_comma,quote"_line | AP6: TRUE | AQ6: 4.17 | AR6: [1,2,3,3] | AS6: 344 | AT6: 行3_列45_中文_Unicode_😀_comma,quote"_line | AU6: FALSE | AV6: 4.22 | AW6: [1,2,3,3] | AX6: 349 | AY6: 行3_列50_中文_Unicode_😀_comma,quote"_line | AZ6: TRUE | BA6: 4.27 | BB6: [1,2,3,3] | BC6: 354 | BD6: 行3_列55_中文_Unicode_😀_comma,quote"_line | BE6: FALSE | BF6: 4.32 | BG6: [1,2,3,3] | BH6: 359 | BI6: 行3_列60_中文_Unicode_😀_comma,quote"_line | BJ6: TRUE | BK6: 4.37 | BL6: [1,2,3,3] | BM6: 364 | BN6: 行3_列65_中文_Unicode_😀_comma,quote"_line | BO6: FALSE | BP6: 4.42 | BQ6: [1,2,3,3] | BR6: 369 | BS6: 行3_列70_中文_Unicode_😀_comma,quote"_line | BT6: TRUE | BU6: 4.47 | BV6: [1,2,3,3] | BW6: 374 | BX6: 行3_列75_中文_Unicode_😀_comma,quote"_line | BY6: FALSE | BZ6: 4.52 | CA6: [1,2,3,3] | CB6: 379 | CC6: 行3_列80_中文_Unicode_😀_comma,quote"_line | CD6: TRUE | CE6: 4.57 | CF6: [1,2,3,3] | CG6: 384 | CH6: 行3_列85_中文_Unicode_😀_comma,quote"_line | CI6: FALSE | CJ6: 4.62 | CK6: [1,2,3,3] | CL6: 389 | CM6: 行3_列90_中文_Unicode_😀_comma,quote"_line | CN6: TRUE | CO6: 4.67 | CP6: [1,2,3,3] | CQ6: 394 | CR6: 行3_列95_中文_Unicode_😀_comma,quote"_line | CS6: FALSE | CT6: 4.72 | CU6: [1,2,3,3] | CV6: 399
A7: 行4_列0_中文_Unicode_😀_comma,quote"_line | B7: FALSE | C7: 5.02 | D7: [1,2,3,4] | E7: 404 | F7: 行4_列5_中文_Unicode_😀_comma,quote"_line | G7: TRUE | H7: 5.07 | I7: [1,2,3,4] | J7: 409 | K7: 行4_列10_中文_Unicode_😀_comma,quote"_line | L7: FALSE | M7: 5.12 | N7: [1,2,3,4] | O7: 414 | P7: 行4_列15_中文_Unicode_😀_comma,quote"_line | Q7: TRUE | R7: 5.17 | S7: [1,2,3,4] | T7: 419 | U7: 行4_列20_中文_Unicode_😀_comma,quote"_line | V7: FALSE | W7: 5.22 | X7: [1,2,3,4] | Y7: 424 | Z7: 行4_列25_中文_Unicode_😀_comma,quote"_line | AA7: TRUE | AB7: 5.27 | AC7: [1,2,3,4] | AD7: 429 | AE7: 行4_列30_中文_Unicode_😀_comma,quote"_line | AF7: FALSE | AG7: 5.32 | AH7: [1,2,3,4] | AI7: 434 | AJ7: 行4_列35_中文_Unicode_😀_comma,quote"_line | AK7: TRUE | AL7: 5.37 | AM7: [1,2,3,4] | AN7: 439 | AO7: 行4_列40_中文_Unicode_😀_comma,quote"_line | AP7: FALSE | AQ7: 5.42 | AR7: [1,2,3,4] | AS7: 444 | AT7: 行4_列45_中文_Unicode_😀_comma,quote"_line | AU7: TRUE | AV7: 5.47 | AW7: [1,2,3,4] | AX7: 449 | AY7: 行4_列50_中文_Unicode_😀_comma,quote"_line | AZ7: FALSE | BA7: 5.52 | BB7: [1,2,3,4] | BC7: 454 | BD7: 行4_列55_中文_Unicode_😀_comma,quote"_line | BE7: TRUE | BF7: 5.57 | BG7: [1,2,3,4] | BH7: 459 | BI7: 行4_列60_中文_Unicode_😀_comma,quote"_line | BJ7: FALSE | BK7: 5.62 | BL7: [1,2,3,4] | BM7: 464 | BN7: 行4_列65_中文_Unicode_😀_comma,quote"_line | BO7: TRUE | BP7: 5.67 | BQ7: [1,2,3,4] | BR7: 469 | BS7: 行4_列70_中文_Unicode_😀_comma,quote"_line | BT7: FALSE | BU7: 5.72 | BV7: [1,2,3,4] | BW7: 474 | BX7: 行4_列75_中文_Unicode_😀_comma,quote"_line | BY7: TRUE | BZ7: 5.77 | CA7: [1,2,3,4] | CB7: 479 | CC7: 行4_列80_中文_Unicode_😀_comma,quote"_line | CD7: FALSE | CE7: 5.82 | CF7: [1,2,3,4] | CG7: 484 | CH7: 行4_列85_中文_Unicode_😀_comma,quote"_line | CI7: TRUE | CJ7: 5.87 | CK7: [1,2,3,4] | CL7: 489 | CM7: 行4_列90_中文_Unicode_😀_comma,quote"_line | CN7: FALSE | CO7: 5.92 | CP7: [1,2,3,4] | CQ7: 494 | CR7: 行4_列95_中文_Unicode_😀_comma,quote"_line | CS7: TRUE | CT7: 5.97 | CU7: [1,2,3,4] | CV7: 499
A8: 行5_列0_中文_Unicode_😀_comma,quote"_line | B8: TRUE | C8: 6.27 | D8: [1,2,3,5] | E8: 504 | F8: 行5_列5_中文_Unicode_😀_comma,quote"_line | G8: FALSE | H8: 6.32 | I8: [1,2,3,5] | J8: 509 | K8: 行5_列10_中文_Unicode_😀_comma,quote"_line | L8: TRUE | M8: 6.37 | N8: [1,2,3,5] | O8: 514 | P8: 行5_列15_中文_Unicode_😀_comma,quote"_line | Q8: FALSE | R8: 6.42 | S8: [1,2,3,5] | T8: 519 | U8: 行5_列20_中文_Unicode_😀_comma,quote"_line | V8: TRUE | W8: 6.47 | X8: [1,2,3,5] | Y8: 524 | Z8: 行5_列25_中文_Unicode_😀_comma,quote"_line | AA8: FALSE | AB8: 6.52 | AC8: [1,2,3,5] | AD8: 529 | AE8: 行5_列30_中文_Unicode_😀_comma,quote"_line | AF8: TRUE | AG8: 6.57 | AH8: [1,2,3,5] | AI8: 534 | AJ8: 行5_列35_中文_Unicode_😀_comma,quote"_line | AK8: FALSE | AL8: 6.62 | AM8: [1,2,3,5] | AN8: 539 | AO8: 行5_列40_中文_Unicode_😀_comma,quote"_line | AP8: TRUE | AQ8: 6.67 | AR8: [1,2,3,5] | AS8: 544 | AT8: 行5_列45_中文_Unicode_😀_comma,quote"_line | AU8: FALSE | AV8: 6.72 | AW8: [1,2,3,5] | AX8: 549 | AY8: 行5_列50_中文_Unicode_😀_comma,quote"_line | AZ8: TRUE | BA8: 6.77 | BB8: [1,2,3,5] | BC8: 554 | BD8: 行5_列55_中文_Unicode_😀_comma,quote"_line | BE8: FALSE | BF8: 6.82 | BG8: [1,2,3,5] | BH8: 559 | BI8: 行5_列60_中文_Unicode_😀_comma,quote"_line | BJ8: TRUE | BK8: 6.87 | BL8: [1,2,3,5] | BM8: 564 | BN8: 行5_列65_中文_Unicode_😀_comma,quote"_line | BO8: FALSE | BP8: 6.92 | BQ8: [1,2,3,5] | BR8: 569 | BS8: 行5_列70_中文_Unicode_😀_comma,quote"_line | BT8: TRUE | BU8: 6.97 | BV8: [1,2,3,5] | BW8: 574 | BX8: 行5_列75_中文_Unicode_😀_comma,quote"_line | BY8: FALSE | BZ8: 7.02 | CA8: [1,2,3,5] | CB8: 579 | CC8: 行5_列80_中文_Unicode_😀_comma,quote"_line | CD8: TRUE | CE8: 7.07 | CF8: [1,2,3,5] | CG8: 584 | CH8: 行5_列85_中文_Unicode_😀_comma,quote"_line | CI8: FALSE | CJ8: 7.12 | CK8: [1,2,3,5] | CL8: 589 | CM8: 行5_列90_中文_Unicode_😀_comma,quote"_line | CN8: TRUE | CO8: 7.17 | CP8: [1,2,3,5] | CQ8: 594 | CR8: 行5_列95_中文_Unicode_😀_comma,quote"_line | CS8: FALSE | CT8: 7.22 | CU8: [1,2,3,5] | CV8: 599
A9: 行6_列0_中文_Unicode_😀_comma,quote"_line | B9: FALSE | C9: 7.52 | D9: [1,2,3,6] | E9: 604 | F9: 行6_列5_中文_Unicode_😀_comma,quote"_line | G9: TRUE | H9: 7.57 | I9: [1,2,3,6] | J9: 609 | K9: 行6_列10_中文_Unicode_😀_comma,quote"_line | L9: FALSE | M9: 7.62 | N9: [1,2,3,6] | O9: 614 | P9: 行6_列15_中文_Unicode_😀_comma,quote"_line | Q9: TRUE | R9: 7.67 | S9: [1,2,3,6] | T9: 619 | U9: 行6_列20_中文_Unicode_😀_comma,quote"_line | V9: FALSE | W9: 7.72 | X9: [1,2,3,6] | Y9: 624 | Z9: 行6_列25_中文_Unicode_😀_comma,quote"_line | AA9: TRUE | AB9: 7.77 | AC9: [1,2,3,6] | AD9: 629 | AE9: 行6_列30_中文_Unicode_😀_comma,quote"_line | AF9: FALSE | AG9: 7.82 | AH9: [1,2,3,6] | AI9: 634 | AJ9: 行6_列35_中文_Unicode_😀_comma,quote"_line | AK9: TRUE | AL9: 7.87 | AM9: [1,2,3,6] | AN9: 639 | AO9: 行6_列40_中文_Unicode_😀_comma,quote"_line | AP9: FALSE | AQ9: 7.92 | AR9: [1,2,3,6] | AS9: 644 | AT9: 行6_列45_中文_Unicode_😀_comma,quote"_line | AU9: TRUE | AV9: 7.97 | AW9: [1,2,3,6] | AX9: 649 | AY9: 行6_列50_中文_Unicode_😀_comma,quote"_line | AZ9: FALSE | BA9: 8.02 | BB9: [1,2,3,6] | BC9: 654 | BD9: 行6_列55_中文_Unicode_😀_comma,quote"_line | BE9: TRUE | BF9: 8.07 | BG9: [1,2,3,6] | BH9: 659 | BI9: 行6_列60_中文_Unicode_😀_comma,quote"_line | BJ9: FALSE | BK9: 8.12 | BL9: [1,2,3,6] | BM9: 664 | BN9: 行6_列65_中文_Unicode_😀_comma,quote"_line | BO9: TRUE | BP9: 8.17 | BQ9: [1,2,3,6] | BR9: 669 | BS9: 行6_列70_中文_Unicode_😀_comma,quote"_line | BT9: FALSE | BU9: 8.22 | BV9: [1,2,3,6] | BW9: 674 | BX9: 行6_列75_中文_Unicode_😀_comma,quote"_line | BY9: TRUE | BZ9: 8.27 | CA9: [1,2,3,6] | CB9: 679 | CC9: 行6_列80_中文_Unicode_😀_comma,quote"_line | CD9: FALSE | CE9: 8.32 | CF9: [1,2,3,6] | CG9: 684 | CH9: 行6_列85_中文_Unicode_😀_comma,quote"_line | CI9: TRUE | CJ9: 8.37 | CK9: [1,2,3,6] | CL9: 689 | CM9: 行6_列90_中文_Unicode_😀_comma,quote"_line | CN9: FALSE | CO9: 8.42 | CP9: [1,2,3,6] | CQ9: 694 | CR9: 行6_列95_中文_Unicode_😀_comma,quote"_line | CS9: TRUE | CT9: 8.47 | CU9: [1,2,3,6] | CV9: 699
A10: 行7_列0_中文_Unicode_😀_comma,quote"_line | B10: TRUE | C10: 8.77 | D10: [1,2,3,7] | E10: 704 | F10: 行7_列5_中文_Unicode_😀_comma,quote"_line | G10: FALSE | H10: 8.82 | I10: [1,2,3,7] | J10: 709 | K10: 行7_列10_中文_Unicode_😀_comma,quote"_line | L10: TRUE | M10: 8.87 | N10: [1,2,3,7] | O10: 714 | P10: 行7_列15_中文_Unicode_😀_comma,quote"_line | Q10: FALSE | R10: 8.92 | S10: [1,2,3,7] | T10: 719 | U10: 行7_列20_中文_Unicode_😀_comma,quote"_line | V10: TRUE | W10: 8.97 | X10: [1,2,3,7] | Y10: 724 | Z10: 行7_列25_中文_Unicode_😀_comma,quote"_line | AA10: FALSE | AB10: 9.02 | AC10: [1,2,3,7] | AD10: 729 | AE10: 行7_列30_中文_Unicode_😀_comma,quote"_line | AF10: TRUE | AG10: 9.07 | AH10: [1,2,3,7] | AI10: 734 | AJ10: 行7_列35_中文_Unicode_😀_comma,quote"_line | AK10: FALSE | AL10: 9.12 | AM10: [1,2,3,7] | AN10: 739 | AO10: 行7_列40_中文_Unicode_😀_comma,quote"_line | AP10: TRUE | AQ10: 9.17 | AR10: [1,2,3,7] | AS10: 744 | AT10: 行7_列45_中文_Unicode_😀_comma,quote"_line | AU10: FALSE | AV10: 9.22 | AW10: [1,2,3,7] | AX10: 749 | AY10: 行7_列50_中文_Unicode_😀_comma,quote"_line | AZ10: TRUE | BA10: 9.27 | BB10: [1,2,3,7] | BC10: 754 | BD10: 行7_列55_中文_Unicode_😀_comma,quote"_line | BE10: FALSE | BF10: 9.32 | BG10: [1,2,3,7] | BH10: 759 | BI10: 行7_列60_中文_Unicode_😀_comma,quote"_line | BJ10: TRUE | BK10: 9.37 | BL10: [1,2,3,7] | BM10: 764 | BN10: 行7_列65_中文_Unicode_😀_comma,quote"_line | BO10: FALSE | BP10: 9.42 | BQ10: [1,2,3,7] | BR10: 769 | BS10: 行7_列70_中文_Unicode_😀_comma,quote"_line | BT10: TRUE | BU10: 9.47 | BV10: [1,2,3,7] | BW10: 774 | BX10: 行7_列75_中文_Unicode_😀_comma,quote"_line | BY10: FALSE | BZ10: 9.52 | CA10: [1,2,3,7] | CB10: 779 | CC10: 行7_列80_中文_Unicode_😀_comma,quote"_line | CD10: TRUE | CE10: 9.57 | CF10: [1,2,3,7] | CG10: 784 | CH10: 行7_列85_中文_Unicode_😀_comma,quote"_line | CI10: FALSE | CJ10: 9.62 | CK10: [1,2,3,7] | CL10: 789 | CM10: 行7_列90_中文_Unicode_😀_comma,quote"_line | CN10: TRUE | CO10: 9.67 | CP10: [1,2,3,7] | CQ10: 794 | CR10: 行7_列95_中文_Unicode_😀_comma,quote"_line | CS10: FALSE | CT10: 9.72 | CU10: [1,2,3,7] | CV10: 799
A11: 行8_列0_中文_Unicode_😀_comma,quote"_line | B11: FALSE | C11: 10.02 | D11: [1,2,3,8] | E11: 804 | F11: 行8_列5_中文_Unicode_😀_comma,quote"_line | G11: TRUE | H11: 10.07 | I11: [1,2,3,8] | J11: 809 | K11: 行8_列10_中文_Unicode_😀_comma,quote"_line | L11: FALSE | M11: 10.12 | N11: [1,2,3,8] | O11: 814 | P11: 行8_列15_中文_Unicode_😀_comma,quote"_line | Q11: TRUE | R11: 10.17 | S11: [1,2,3,8] | T11: 819 | U11: 行8_列20_中文_Unicode_😀_comma,quote"_line | V11: FALSE | W11: 10.22 | X11: [1,2,3,8] | Y11: 824 | Z11: 行8_列25_中文_Unicode_😀_comma,quote"_line | AA11: TRUE | AB11: 10.27 | AC11: [1,2,3,8] | AD11: 829 | AE11: 行8_列30_中文_Unicode_😀_comma,quote"_line | AF11: FALSE | AG11: 10.32 | AH11: [1,2,3,8] | AI11: 834 | AJ11: 行8_列35_中文_Unicode_😀_comma,quote"_line | AK11: TRUE | AL11: 10.37 | AM11: [1,2,3,8] | AN11: 839 | AO11: 行8_列40_中文_Unicode_😀_comma,quote"_line | AP11: FALSE | AQ11: 10.42 | AR11: [1,2,3,8] | AS11: 844 | AT11: 行8_列45_中文_Unicode_😀_comma,quote"_line | AU11: TRUE | AV11: 10.47 | AW11: [1,2,3,8] | AX11: 849 | AY11: 行8_列50_中文_Unicode_😀_comma,quote"_line | AZ11: FALSE | BA11: 10.52 | BB11: [1,2,3,8] | BC11: 854 | BD11: 行8_列55_中文_Unicode_😀_comma,quote"_line | BE11: TRUE | BF11: 10.57 | BG11: [1,2,3,8] | BH11: 859 | BI11: 行8_列60_中文_Unicode_😀_comma,quote"_line | BJ11: FALSE | BK11: 10.62 | BL11: [1,2,3,8] | BM11: 864 | BN11: 行8_列65_中文_Unicode_😀_comma,quote"_line | BO11: TRUE | BP11: 10.67 | BQ11: [1,2,3,8] | BR11: 869 | BS11: 行8_列70_中文_Unicode_😀_comma,quote"_line | BT11: FALSE | BU11: 10.72 | BV11: [1,2,3,8] | BW11: 874 | BX11: 行8_列75_中文_Unicode_😀_comma,quote"_line | BY11: TRUE | BZ11: 10.77 | CA11: [1,2,3,8] | CB11: 879 | CC11: 行8_列80_中文_Unicode_😀_comma,quote"_line | CD11: FALSE | CE11: 10.82 | CF11: [1,2,3,8] | CG11: 884 | CH11: 行8_列85_中文_Unicode_😀_comma,quote"_line | CI11: TRUE | CJ11: 10.87 | CK11: [1,2,3,8] | CL11: 889 | CM11: 行8_列90_中文_Unicode_😀_comma,quote"_line | CN11: FALSE | CO11: 10.92 | CP11: [1,2,3,8] | CQ11: 894 | CR11: 行8_列95_中文_Unicode_😀_comma,quote"_line | CS11: TRUE | CT11: 10.97 | CU11: [1,2,3,8] | CV11: 899
A12: 行9_列0_中文_Unicode_😀_comma,quote"_line | B12: TRUE | C12: 11.27 | D12: [1,2,3,9] | E12: 904 | F12: 行9_列5_中文_Unicode_😀_comma,quote"_line | G12: FALSE | H12: 11.32 | I12: [1,2,3,9] | J12: 909 | K12: 行9_列10_中文_Unicode_😀_comma,quote"_line | L12: TRUE | M12: 11.37 | N12: [1,2,3,9] | O12: 914 | P12: 行9_列15_中文_Unicode_😀_comma,quote"_line | Q12: FALSE | R12: 11.42 | S12: [1,2,3,9] | T12: 919 | U12: 行9_列20_中文_Unicode_😀_comma,quote"_line | V12: TRUE | W12: 11.47 | X12: [1,2,3,9] | Y12: 924 | Z12: 行9_列25_中文_Unicode_😀_comma,quote"_line | AA12: FALSE | AB12: 11.52 | AC12: [1,2,3,9] | AD12: 929 | AE12: 行9_列30_中文_Unicode_😀_comma,quote"_line | AF12: TRUE | AG12: 11.57 | AH12: [1,2,3,9] | AI12: 934 | AJ12: 行9_列35_中文_Unicode_😀_comma,quote"_line | AK12: FALSE | AL12: 11.62 | AM12: [1,2,3,9] | AN12: 939 | AO12: 行9_列40_中文_Unicode_😀_comma,quote"_line | AP12: TRUE | AQ12: 11.67 | AR12: [1,2,3,9] | AS12: 944 | AT12: 行9_列45_中文_Unicode_😀_comma,quote"_line | AU12: FALSE | AV12: 11.72 | AW12: [1,2,3,9] | AX12: 949 | AY12: 行9_列50_中文_Unicode_😀_comma,quote"_line | AZ12: TRUE | BA12: 11.77 | BB12: [1,2,3,9] | BC12: 954 | BD12: 行9_列55_中文_Unicode_😀_comma,quote"_line | BE12: FALSE | BF12: 11.82 | BG12: [1,2,3,9] | BH12: 959 | BI12: 行9_列60_中文_Unicode_😀_comma,quote"_line | BJ12: TRUE | BK12: 11.87 | BL12: [1,2,3,9] | BM12: 964 | BN12: 行9_列65_中文_Unicode_😀_comma,quote"_line | BO12: FALSE | BP12: 11.92 | BQ12: [1,2,3,9] | BR12: 969 | BS12: 行9_列70_中文_Unicode_😀_comma,quote"_line | BT12: TRUE | BU12: 11.97 | BV12: [1,2,3,9] | BW12: 974 | BX12: 行9_列75_中文_Unicode_😀_comma,quote"_line | BY12: FALSE | BZ12: 12.02 | CA12: [1,2,3,9] | CB12: 979 | CC12: 行9_列80_中文_Unicode_😀_comma,quote"_line | CD12: TRUE | CE12: 12.07 | CF12: [1,2,3,9] | CG12: 984 | CH12: 行9_列85_中文_Unicode_😀_comma,quote"_line | CI12: FALSE | CJ12: 12.12 | CK12: [1,2,3,9] | CL12: 989 | CM12: 行9_列90_中文_Unicode_😀_comma,quote"_line | CN12: TRUE | CO12: 12.17 | CP12: [1,2,3,9] | CQ12: 994 | CR12: 行9_列95_中文_Unicode_😀_comma,quote"_line | CS12: FALSE | CT12: 12.22 | CU12: [1,2,3,9] | CV12: 999
A13: 行10_列0_中文_Unicode_😀_comma,quote"_line | B13: FALSE | C13: 12.52 | D13: [1,2,3,10] | E13: 1004 | F13: 行10_列5_中文_Unicode_😀_comma,quote"_line | G13: TRUE | H13: 12.57 | I13: [1,2,3,10] | J13: 1009 | K13: 行10_列10_中文_Unicode_😀_comma,quote"_line | L13: FALSE | M13: 12.62 | N13: [1,2,3,10] | O13: 1014 | P13: 行10_列15_中文_Unicode_😀_comma,quote"_line | Q13: TRUE | R13: 12.67 | S13: [1,2,3,10] | T13: 1019 | U13: 行10_列20_中文_Unicode_😀_comma,quote"_line | V13: FALSE | W13: 12.72 | X13: [1,2,3,10] | Y13: 1024 | Z13: 行10_列25_中文_Unicode_😀_comma,quote"_line | AA13: TRUE | AB13: 12.77 | AC13: [1,2,3,10] | AD13: 1029 | AE13: 行10_列30_中文_Unicode_😀_comma,quote"_line | AF13: FALSE | AG13: 12.82 | AH13: [1,2,3,10] | AI13: 1034 | AJ13: 行10_列35_中文_Unicode_😀_comma,quote"_line | AK13: TRUE | AL13: 12.87 | AM13: [1,2,3,10] | AN13: 1039 | AO13: 行10_列40_中文_Unicode_😀_comma,quote"_line | AP13: FALSE | AQ13: 12.92 | AR13: [1,2,3,10] | AS13: 1044 | AT13: 行10_列45_中文_Unicode_😀_comma,quote"_line | AU13: TRUE | AV13: 12.97 | AW13: [1,2,3,10] | AX13: 1049 | AY13: 行10_列50_中文_Unicode_😀_comma,quote"_line | AZ13: FALSE | BA13: 13.02 | BB13: [1,2,3,10] | BC13: 1054 | BD13: 行10_列55_中文_Unicode_😀_comma,quote"_line | BE13: TRUE | BF13: 13.07 | BG13: [1,2,3,10] | BH13: 1059 | BI13: 行10_列60_中文_Unicode_😀_comma,quote"_line | BJ13: FALSE | BK13: 13.12 | BL13: [1,2,3,10] | BM13: 1064 | BN13: 行10_列65_中文_Unicode_😀_comma,quote"_line | BO13: TRUE | BP13: 13.17 | BQ13: [1,2,3,10] | BR13: 1069 | BS13: 行10_列70_中文_Unicode_😀_comma,quote"_line | BT13: FALSE | BU13: 13.22 | BV13: [1,2,3,10] | BW13: 1074 | BX13: 行10_列75_中文_Unicode_😀_comma,quote"_line | BY13: TRUE | BZ13: 13.27 | CA13: [1,2,3,10] | CB13: 1079 | CC13: 行10_列80_中文_Unicode_😀_comma,quote"_line | CD13: FALSE | CE13: 13.32 | CF13: [1,2,3,10] | CG13: 1084 | CH13: 行10_列85_中文_Unicode_😀_comma,quote"_line | CI13: TRUE | CJ13: 13.37 | CK13: [1,2,3,10] | CL13: 1089 | CM13: 行10_列90_中文_Unicode_😀_comma,quote"_line | CN13: FALSE | CO13: 13.42 | CP13: [1,2,3,10] | CQ13: 1094 | CR13: 行10_列95_中文_Unicode_😀_comma,quote"_line | CS13: TRUE | CT13: 13.47 | CU13: [1,2,3,10] | CV13: 1099
A14: 行11_列0_中文_Unicode_😀_comma,quote"_line | B14: TRUE | C14: 13.77 | D14: [1,2,3,11] | E14: 1104 | F14: 行11_列5_中文_Unicode_😀_comma,quote"_line | G14: FALSE | H14: 13.82 | I14: [1,2,3,11] | J14: 1109 | K14: 行11_列10_中文_Unicode_😀_comma,quote"_line | L14: TRUE | M14: 13.87 | N14: [1,2,3,11] | O14: 1114 | P14: 行11_列15_中文_Unicode_😀_comma,quote"_line | Q14: FALSE | R14: 13.92 | S14: [1,2,3,11] | T14: 1119 | U14: 行11_列20_中文_Unicode_😀_comma,quote"_line | V14: TRUE | W14: 13.97 | X14: [1,2,3,11] | Y14: 1124 | Z14: 行11_列25_中文_Unicode_😀_comma,quote"_line | AA14: FALSE | AB14: 14.02 | AC14: [1,2,3,11] | AD14: 1129 | AE14: 行11_列30_中文_Unicode_😀_comma,quote"_line | AF14: TRUE | AG14: 14.07 | AH14: [1,2,3,11] | AI14: 1134 | AJ14: 行11_列35_中文_Unicode_😀_comma,quote"_line | AK14: FALSE | AL14: 14.12 | AM14: [1,2,3,11] | AN14: 1139 | AO14: 行11_列40_中文_Unicode_😀_comma,quote"_line | AP14: TRUE | AQ14: 14.17 | AR14: [1,2,3,11] | AS14: 1144 | AT14: 行11_列45_中文_Unicode_😀_comma,quote"_line | AU14: FALSE | AV14: 14.22 | AW14: [1,2,3,11] | AX14: 1149 | AY14: 行11_列50_中文_Unicode_😀_comma,quote"_line | AZ14: TRUE | BA14: 14.27 | BB14: [1,2,3,11] | BC14: 1154 | BD14: 行11_列55_中文_Unicode_😀_comma,quote"_line | BE14: FALSE | BF14: 14.32 | BG14: [1,2,3,11] | BH14: 1159 | BI14: 行11_列60_中文_Unicode_😀_comma,quote"_line | BJ14: TRUE | BK14: 14.37 | BL14: [1,2,3,11] | BM14: 1164 | BN14: 行11_列65_中文_Unicode_😀_comma,quote"_line | BO14: FALSE | BP14: 14.42 | BQ14: [1,2,3,11] | BR14: 1169 | BS14: 行11_列70_中文_Unicode_😀_comma,quote"_line | BT14: TRUE | BU14: 14.47 | BV14: [1,2,3,11] | BW14: 1174 | BX14: 行11_列75_中文_Unicode_😀_comma,quote"_line | BY14: FALSE | BZ14: 14.52 | CA14: [1,2,3,11] | CB14: 1179 | CC14: 行11_列80_中文_Unicode_😀_comma,quote"_line | CD14: TRUE | CE14: 14.57 | CF14: [1,2,3,11] | CG14: 1184 | CH14: 行11_列85_中文_Unicode_😀_comma,quote"_line | CI14: FALSE | CJ14: 14.62 | CK14: [1,2,3,11] | CL14: 1189 | CM14: 行11_列90_中文_Unicode_😀_comma,quote"_line | CN14: TRUE | CO14: 14.67 | CP14: [1,2,3,11] | CQ14: 1194 | CR14: 行11_列95_中文_Unicode_😀_comma,quote"_line | CS14: FALSE | CT14: 14.72 | CU14: [1,2,3,11] | CV14: 1199
A15: 行12_列0_中文_Unicode_😀_comma,quote"_line | B15: FALSE | C15: 15.02 | D15: [1,2,3,12] | E15: 1204 | F15: 行12_列5_中文_Unicode_😀_comma,quote"_line | G15: TRUE | H15: 15.07 | I15: [1,2,3,12] | J15: 1209 | K15: 行12_列10_中文_Unicode_😀_comma,quote"_line | L15: FALSE | M15: 15.12 | N15: [1,2,3,12] | O15: 1214 | P15: 行12_列15_中文_Unicode_😀_comma,quote"_line | Q15: TRUE | R15: 15.17 | S15: [1,2,3,12] | T15: 1219 | U15: 行12_列20_中文_Unicode_😀_comma,quote"_line | V15: FALSE | W15: 15.22 | X15: [1,2,3,12] | Y15: 1224 | Z15: 行12_列25_中文_Unicode_😀_comma,quote"_line | AA15: TRUE | AB15: 15.27 | AC15: [1,2,3,12] | AD15: 1229 | AE15: 行12_列30_中文_Unicode_😀_comma,quote"_line | AF15: FALSE | AG15: 15.32 | AH15: [1,2,3,12] | AI15: 1234 | AJ15: 行12_列35_中文_Unicode_😀_comma,quote"_line | AK15: TRUE | AL15: 15.37 | AM15: [1,2,3,12] | AN15: 1239 | AO15: 行12_列40_中文_Unicode_😀_comma,quote"_line | AP15: FALSE | AQ15: 15.42 | AR15: [1,2,3,12] | AS15: 1244 | AT15: 行12_列45_中文_Unicode_😀_comma,quote"_line | AU15: TRUE | AV15: 15.47 | AW15: [1,2,3,12] | AX15: 1249 | AY15: 行12_列50_中文_Unicode_😀_comma,quote"_line | AZ15: FALSE | BA15: 15.52 | BB15: [1,2,3,12] | BC15: 1254 | BD15: 行12_列55_中文_Unicode_😀_comma,quote"_line | BE15: TRUE | BF15: 15.57 | BG15: [1,2,3,12] | BH15: 1259 | BI15: 行12_列60_中文_Unicode_😀_comma,quote"_line | BJ15: FALSE | BK15: 15.62 | BL15: [1,2,3,12] | BM15: 1264 | BN15: 行12_列65_中文_Unicode_😀_comma,quote"_line | BO15: TRUE | BP15: 15.67 | BQ15: [1,2,3,12] | BR15: 1269 | BS15: 行12_列70_中文_Unicode_😀_comma,quote"_line | BT15: FALSE | BU15: 15.72 | BV15: [1,2,3,12] | BW15: 1274 | BX15: 行12_列75_中文_Unicode_😀_comma,quote"_line | BY15: TRUE | BZ15: 15.77 | CA15: [1,2,3,12] | CB15: 1279 | CC15: 行12_列80_中文_Unicode_😀_comma,quote"_line | CD15: FALSE | CE15: 15.82 | CF15: [1,2,3,12] | CG15: 1284 | CH15: 行12_列85_中文_Unicode_😀_comma,quote"_line | CI15: TRUE | CJ15: 15.87 | CK15: [1,2,3,12] | CL15: 1289 | CM15: 行12_列90_中文_Unicode_😀_comma,quote"_line | CN15: FALSE | CO15: 15.92 | CP15: [1,2,3,12] | CQ15: 1294 | CR15: 行12_列95_中文_Unicode_😀_comma,quote"_line | CS15: TRUE | CT15: 15.97 | CU15: [1,2,3,12] | CV15: 1299
... A303: 行300_列0_中文_Unicode_😀_comma,quote"_line | B303: FALSE | C303: 375.02 | D303: [1,2,3,300] | E303: 30004 | F303: 行300_列5_中文_Unicode_😀_comma,quote"_line | G303: TRUE | H303: 375.07 | I303: [1,2,3,300] | J303: 30009 | K303: 行300_列10_中文_Unicode_😀_comma,quote"_line | L303: FALSE | M303: 375.12 | N303: [1,2,3,300] | O303: 30014 | P303: 行300_列15_中文_Unicode_😀_comma,quote"_line | Q303: TRUE | R303: 375.17 | S303: [1,2,3,300] | T303: 30019 | U303: 行300_列20_中文_Unicode_😀_comma,quote"_line | V303: FALSE | W303: 375.22 | X303: [1,2,3,300] | Y303: 30024 | Z303: 行300_列25_中文_Unicode_😀_comma,quote"_line | AA303: TRUE | AB303: 375.27 | AC303: [1,2,3,300] | AD303: 30029 | AE303: 行300_列30_中文_Unicode_😀_comma,quote"_line | AF303: FALSE | AG303: 375.32 | AH303: [1,2,3,300] | AI303: 30034 | AJ303: 行300_列35_中文_Unicode_😀_comma,quote"_line | AK303: TRUE | AL303: 375.37 | AM303: [1,2,3,300] | AN303: 30039 | AO303: 行300_列40_中文_Unicode_😀_comma,quote"_line | AP303: FALSE | AQ303: 375.42 | AR303: [1,2,3,300] | AS303: 30044 | AT303: 行300_列45_中文_Unicode_😀_comma,quote"_line | AU303: TRUE | AV303: 375.47 | AW303: [1,2,3,300] | AX303: 30049 | AY303: 行300_列50_中文_Unicode_😀_comma,quote"_line | AZ303: FALSE | BA303: 375.52 | BB303: [1,2,3,300] | BC303: 30054 | BD303: 行300_列55_中文_Unicode_😀_comma,quote"_line | BE303: TRUE | BF303: 375.57 | BG303: [1,2,3,300] | BH303: 30059 | BI303: 行300_列60_中文_Unicode_😀_comma,quote"_line | BJ303: FALSE | BK303: 375.62 | BL303: [1,2,3,300] | BM303: 30064 | BN303: 行300_列65_中文_Unicode_😀_comma,quote"_line | BO303: TRUE | BP303: 375.67 | BQ303: [1,2,3,300] | BR303: 30069 | BS303: 行300_列70_中文_Unicode_😀_comma,quote"_line | BT303: FALSE | BU303: 375.72 | BV303: [1,2,3,300] | BW303: 30074 | BX303: 行300_列75_中文_Unicode_😀_comma,quote"_line | BY303: TRUE | BZ303: 375.77 | CA303: [1,2,3,300] | CB303: 30079 | CC303: 行300_列80_中文_Unicode_😀_comma,quote"_line | CD303: FALSE | CE303: 375.82 | CF303: [1,2,3,300] | CG303: 30084 | CH303: 行300_列85_中文_Unicode_😀_comma,quote"_line | CI303: TRUE | CJ303: 375.87 | CK303: [1,2,3,300] | CL303: 30089 | CM303: 行300_列90_中文_Unicode_😀_comma,quote"_line | CN303: FALSE | CO303: 375.92 | CP303: [1,2,3,300] | CQ303: 30094 | CR303: 行300_列95_中文_Unicode_😀_comma,quote"_line | CS303: TRUE | CT303: 375.97 | CU303: [1,2,3,300] | CV303: 30099

Sheet HugeRows
A1: id,key | B1: code | C1: title | D1: active | E1: count | F1: ratio | G1: created | H1: values | I1: point | J1: dict | K1: memo | L1: tail
A2: int | B2: string | C2: string | D2: bool | E2: long | F2: double | G2: DateTime | H2: List<int> | I2: Vector3 | J2: Dictionary<string, int> | K2: string | L2: string
A3: 大数据行字段 1 | B3: 大数据行字段 2 | C3: 大数据行字段 3 | D3: 大数据行字段 4 | E3: 大数据行字段 5 | F3: 大数据行字段 6 | G3: 大数据行字段 7 | H3: 大数据行字段 8 | I3: 大数据行字段 9 | J3: 大数据行字段 10 | K3: 大数据行字段 11 | L3: 大数据行字段 12
A4: 100 | B4: 行1_列1_中文_Unicode_😀_comma,quote"_line | C4: 行1_列2_中文_Unicode_😀_comma,quote"_line | D4: TRUE | E4: 104 | F4: 1.3 | G4: 46236.504 | H4: [1,2,3,1] | I4: {"x":1,"y":2,"z":3} | J4: {"alpha":1,"row":1} | K4: 行1_列10_中文_Unicode_😀_comma,quote"_line | L4: 行1_列11_中文_Unicode_😀_comma,quote"_line
A5: 200 | B5: 行2_列1_中文_Unicode_😀_comma,quote"_line | C5: 行2_列2_中文_Unicode_😀_comma,quote"_line | D5: FALSE | E5: 204 | F5: 2.55 | G5: 46237.504 | H5: [1,2,3,2] | I5: {"x":2,"y":3,"z":4} | J5: {"alpha":1,"row":2} | K5: 行2_列10_中文_Unicode_😀_comma,quote"_line | L5: 行2_列11_中文_Unicode_😀_comma,quote"_line
A6: 300 | B6: 行3_列1_中文_Unicode_😀_comma,quote"_line | C6: 行3_列2_中文_Unicode_😀_comma,quote"_line | D6: TRUE | E6: 304 | F6: 3.8 | G6: 46238.504 | H6: [1,2,3,3] | I6: {"x":3,"y":4,"z":5} | J6: {"alpha":1,"row":3} | K6: 行3_列10_中文_Unicode_😀_comma,quote"_line | L6: 行3_列11_中文_Unicode_😀_comma,quote"_line
A7: 400 | B7: 行4_列1_中文_Unicode_😀_comma,quote"_line | C7: 行4_列2_中文_Unicode_😀_comma,quote"_line | D7: FALSE | E7: 404 | F7: 5.05 | G7: 46239.504 | H7: [1,2,3,4] | I7: {"x":4,"y":5,"z":6} | J7: {"alpha":1,"row":4} | K7: 行4_列10_中文_Unicode_😀_comma,quote"_line | L7: 行4_列11_中文_Unicode_😀_comma,quote"_line
A8: 500 | B8: 行5_列1_中文_Unicode_😀_comma,quote"_line | C8: 行5_列2_中文_Unicode_😀_comma,quote"_line | D8: TRUE | E8: 504 | F8: 6.3 | G8: 46240.504 | H8: [1,2,3,5] | I8: {"x":5,"y":6,"z":7} | J8: {"alpha":1,"row":5} | K8: 行5_列10_中文_Unicode_😀_comma,quote"_line | L8: 行5_列11_中文_Unicode_😀_comma,quote"_line
A9: 600 | B9: 行6_列1_中文_Unicode_😀_comma,quote"_line | C9: 行6_列2_中文_Unicode_😀_comma,quote"_line | D9: FALSE | E9: 604 | F9: 7.55 | G9: 46241.504 | H9: [1,2,3,6] | I9: {"x":6,"y":7,"z":8} | J9: {"alpha":1,"row":6} | K9: 行6_列10_中文_Unicode_😀_comma,quote"_line | L9: 行6_列11_中文_Unicode_😀_comma,quote"_line
A10: 700 | B10: 行7_列1_中文_Unicode_😀_comma,quote"_line | C10: 行7_列2_中文_Unicode_😀_comma,quote"_line | D10: TRUE | E10: 704 | F10: 8.8 | G10: 46242.504 | H10: [1,2,3,7] | I10: {"x":7,"y":8,"z":9} | J10: {"alpha":1,"row":7} | K10: 行7_列10_中文_Unicode_😀_comma,quote"_line | L10: 行7_列11_中文_Unicode_😀_comma,quote"_line
A11: 800 | B11: 行8_列1_中文_Unicode_😀_comma,quote"_line | C11: 行8_列2_中文_Unicode_😀_comma,quote"_line | D11: FALSE | E11: 804 | F11: 10.05 | G11: 46243.504 | H11: [1,2,3,8] | I11: {"x":8,"y":9,"z":10} | J11: {"alpha":1,"row":8} | K11: 行8_列10_中文_Unicode_😀_comma,quote"_line | L11: 行8_列11_中文_Unicode_😀_comma,quote"_line
A12: 900 | B12: 行9_列1_中文_Unicode_😀_comma,quote"_line | C12: 行9_列2_中文_Unicode_😀_comma,quote"_line | D12: TRUE | E12: 904 | F12: 11.3 | G12: 46244.504 | H12: [1,2,3,9] | I12: {"x":9,"y":10,"z":11} | J12: {"alpha":1,"row":9} | K12: 行9_列10_中文_Unicode_😀_comma,quote"_line | L12: 行9_列11_中文_Unicode_😀_comma,quote"_line
A13: 1000 | B13: 行10_列1_中文_Unicode_😀_comma,quote"_line | C13: 行10_列2_中文_Unicode_😀_comma,quote"_line | D13: FALSE | E13: 1004 | F13: 12.55 | G13: 46245.504 | H13: [1,2,3,10] | I13: {"x":10,"y":11,"z":12} | J13: {"alpha":1,"row":10} | K13: 行10_列10_中文_Unicode_😀_comma,quote"_line | L13: 行10_列11_中文_Unicode_😀_comma,quote"_line
A14: 1100 | B14: 行11_列1_中文_Unicode_😀_comma,quote"_line | C14: 行11_列2_中文_Unicode_😀_comma,quote"_line | D14: TRUE | E14: 1104 | F14: 13.8 | G14: 46246.504 | H14: [1,2,3,11] | I14: {"x":11,"y":12,"z":13} | J14: {"alpha":1,"row":11} | K14: 行11_列10_中文_Unicode_😀_comma,quote"_line | L14: 行11_列11_中文_Unicode_😀_comma,quote"_line
A15: 1200 | B15: 行12_列1_中文_Unicode_😀_comma,quote"_line | C15: 行12_列2_中文_Unicode_😀_comma,quote"_line | D15: FALSE | E15: 1204 | F15: 15.05 | G15: 46247.504 | H15: [1,2,3,12] | I15: {"x":12,"y":13,"z":14} | J15: {"alpha":1,"row":12} | K15: 行12_列10_中文_Unicode_😀_comma,quote"_line | L15: 行12_列11_中文_Unicode_😀_comma,quote"_line
... A10003: 1000000 | B10003: 行10000_列1_中文_Unicode_😀_comma,quote"_line | C10003: 行10000_列2_中文_Unicode_😀_comma,quote"_line | D10003: FALSE | E10003: 1000004 | F10003: 12500.05 | G10003: 46239.504 | H10003: [1,2,3,10000] | I10003: {"x":10000,"y":10001,"z":10002} | J10003: {"alpha":1,"row":10000} | K10003: 行10000_列10_中文_Unicode_😀_comma,quote"_line | L10003: 行10000_列11_中文_Unicode_😀_comma,quote"_line

Sheet ComplexTypes
A1: id,key | B1: tiny | C1: small | D1: normal | E1: big | F1: unsigned | G1: single | H1: real | I1: flag | J1: nullableValue | K1: when | L1: numbers | M1: words | N1: vec2 | O1: vec3 | P1: map | Q1: escaped | R1: emptyText
A2: int | B2: byte | C2: short | D2: int | E2: long | F2: uint | G2: float | H2: double | I2: bool | J2: int? | K2: DateTime | L2: List<int> | M2: string[] | N2: Vector2 | O2: Vector3 | P2: Dictionary<string, int> | Q2: string | R2: string
A3: 复杂类型 1 | B3: 复杂类型 2 | C3: 复杂类型 3 | D3: 复杂类型 4 | E3: 复杂类型 5 | F3: 复杂类型 6 | G3: 复杂类型 7 | H3: 复杂类型 8 | I3: 复杂类型 9 | J3: 复杂类型 10 | K3: 复杂类型 11 | L3: 复杂类型 12 | M3: 复杂类型 13 | N3: 复杂类型 14 | O3: 复杂类型 15 | P3: 复杂类型 16 | Q3: 复杂类型 17 | R3: 复杂类型 18
A4: 1 | B4: 0 | C4: -32768 | D4: -2147483648 | E4: -9.0071993e+15 | F4: 0 | G4: 1.1754943e-38 | H4: 2.2250739e-308 | I4: FALSE | J4: 10 | K4: 46023.001 | L4: [1,2,3] | M4: ["A1","中文","emoji-1"] | N4: {"x":1,"y":1.5} | O4: {"x":1,"y":2,"z":3} | P4: {"alpha":1,"row":4} | Q4: 行1 制表符 换行\反斜杠"引号,逗号 | R4: 文本1
A5: 2 | B5: 255 | C5: 32767 | D5: 2147483647 | E5: 9.0071993e+15 | F5: 4294967295 | G5: 3.4028234e+38 | H5: 1.7976931e+308 | I5: TRUE | J5: 20 | K5: 46024.001 | L5: [2,3,4] | M5: ["A2","中文","emoji-2"] | N5: {"x":2,"y":2.5} | O5: {"x":2,"y":3,"z":4} | P5: {"alpha":2,"row":5} | Q5: 行2 制表符 换行\反斜杠"引号,逗号 | R5: 文本2
A6: 3 | B6: 2 | C6: -29997 | D6: -999997 | E6: 9000000003 | F6: 2000000 | G6: 0.3 | H6: 1 | I6: FALSE | J6: 30 | K6: 46025.002 | L6: [3,4,5] | M6: ["A3","中文","emoji-3"] | N6: {"x":3,"y":3.5} | O6: {"x":3,"y":4,"z":5} | P6: {"alpha":3,"row":6} | Q6: 行3 制表符 换行\反斜杠"引号,逗号 | R6: 文本3
A7: 4 | B7: 3 | C7: -29996 | D7: -999996 | E7: 9000000004 | F7: 3000000 | G7: 0.4 | H7: 1.3333333 | I7: TRUE | J7: 40 | K7: 46026.003 | L7: [4,5,6] | M7: ["A4","中文","emoji-4"] | N7: {"x":4,"y":4.5} | O7: {"x":4,"y":5,"z":6} | P7: {"alpha":4,"row":7} | Q7: 行4 制表符 换行\反斜杠"引号,逗号 | R7: 文本4
A8: 5 | B8: 4 | C8: -29995 | D8: -999995 | E8: 9000000005 | F8: 4000000 | G8: 0.5 | H8: 1.6666667 | I8: FALSE | J8: 50 | K8: 46027.003 | L8: [5,6,7] | M8: ["A5","中文","emoji-5"] | N8: {"x":5,"y":5.5} | O8: {"x":5,"y":6,"z":7} | P8: {"alpha":5,"row":8} | Q8: 行5 制表符 换行\反斜杠"引号,逗号 | R8: 文本5
A9: 6 | B9: 5 | C9: -29994 | D9: -999994 | E9: 9000000006 | F9: 5000000 | G9: 0.6 | H9: 2 | I9: TRUE | J9: 60 | K9: 46028.004 | L9: [6,7,8] | M9: ["A6","中文","emoji-6"] | N9: {"x":6,"y":6.5} | O9: {"x":6,"y":7,"z":8} | P9: {"alpha":6,"row":9} | Q9: 行6 制表符 换行\反斜杠"引号,逗号 | R9: 文本6
A10: 7 | B10: 6 | C10: -29993 | D10: -999993 | E10: 9000000007 | F10: 6000000 | G10: 0.7 | H10: 2.3333333 | I10: FALSE | J10: 70 | K10: 46029.005 | L10: [7,8,9] | M10: ["A7","中文","emoji-7"] | N10: {"x":7,"y":7.5} | O10: {"x":7,"y":8,"z":9} | P10: {"alpha":7,"row":10} | Q10: 行7 制表符 换行\反斜杠"引号,逗号 | R10: 文本7
A11: 8 | B11: 7 | C11: -29992 | D11: -999992 | E11: 9000000008 | F11: 7000000 | G11: 0.8 | H11: 2.6666667 | I11: TRUE | J11: 80 | K11: 46030.006 | L11: [8,9,10] | M11: ["A8","中文","emoji-8"] | N11: {"x":8,"y":8.5} | O11: {"x":8,"y":9,"z":10} | P11: {"alpha":8,"row":11} | Q11: 行8 制表符 换行\反斜杠"引号,逗号 | R11: 文本8
A12: 9 | B12: 8 | C12: -29991 | D12: -999991 | E12: 9000000009 | F12: 8000000 | G12: 0.9 | H12: 3 | I12: FALSE | J12: 90 | K12: 46031.006 | L12: [9,10,11] | M12: ["A9","中文","emoji-9"] | N12: {"x":9,"y":9.5} | O12: {"x":9,"y":10,"z":11} | P12: {"alpha":9,"row":12} | Q12: 行9 制表符 换行\反斜杠"引号,逗号 | R12: 文本9
A13: 10 | B13: 9 | C13: -29990 | D13: -999990 | E13: 9000000010 | F13: 9000000 | G13: 1 | H13: 3.3333333 | I13: TRUE | K13: 46032.007 | L13: [10,11,12] | M13: ["A10","中文","emoji-10"] | N13: {"x":10,"y":10.5} | O13: {"x":10,"y":11,"z":12} | P13: {"alpha":10,"row":13} | Q13: 行10 制表符 换行\反斜杠"引号,逗号 | R13: 文本10
A14: 11 | B14: 10 | C14: -29989 | D14: -999989 | E14: 9000000011 | F14: 10000000 | G14: 1.1 | H14: 3.6666667 | I14: FALSE | J14: 110 | K14: 46033.008 | L14: [11,12,13] | M14: ["A11","中文","emoji-11"] | N14: {"x":11,"y":11.5} | O14: {"x":11,"y":12,"z":13} | P14: {"alpha":11,"row":14} | Q14: 行11 制表符 换行\反斜杠"引号,逗号 | R14: 文本11
A15: 12 | B15: 11 | C15: -29988 | D15: -999988 | E15: 9000000012 | F15: 11000000 | G15: 1.2 | H15: 4 | I15: TRUE | J15: 120 | K15: 46034.008 | L15: [12,13,14] | M15: ["A12","中文","emoji-12"] | N15: {"x":12,"y":12.5} | O15: {"x":12,"y":13,"z":14} | P15: {"alpha":12,"row":15} | Q15: 行12 制表符 换行\反斜杠"引号,逗号 | R15: 文本12
A16: 13 | B16: 12 | C16: -29987 | D16: -999987 | E16: 9000000013 | F16: 12000000 | G16: 1.3 | H16: 4.3333333 | I16: FALSE | J16: 130 | K16: 46035.009 | L16: [13,14,15] | M16: ["A13","中文","emoji-13"] | N16: {"x":13,"y":13.5} | O16: {"x":13,"y":14,"z":15} | P16: {"alpha":13,"row":16} | Q16: 行13 制表符 换行\反斜杠"引号,逗号 | R16: 文本13
A17: 14 | B17: 13 | C17: -29986 | D17: -999986 | E17: 9000000014 | F17: 13000000 | G17: 1.4 | H17: 4.6666667 | I17: TRUE | J17: 140 | K17: 46036.01 | L17: [14,15,16] | M17: ["A14","中文","emoji-14"] | N17: {"x":14,"y":14.5} | O17: {"x":14,"y":15,"z":16} | P17: {"alpha":14,"row":17} | Q17: 行14 制表符 换行\反斜杠"引号,逗号 | R17: 文本14
A18: 15 | B18: 14 | C18: -29985 | D18: -999985 | E18: 9000000015 | F18: 14000000 | G18: 1.5 | H18: 5 | I18: FALSE | J18: 150 | K18: 46037.01 | L18: [15,16,17] | M18: ["A15","中文","emoji-15"] | N18: {"x":15,"y":15.5} | O18: {"x":15,"y":16,"z":17} | P18: {"alpha":15,"row":18} | Q18: 行15 制表符 换行\反斜杠"引号,逗号
A19: 16 | B19: 15 | C19: -29984 | D19: -999984 | E19: 9000000016 | F19: 15000000 | G19: 1.6 | H19: 5.3333333 | I19: TRUE | J19: 160 | K19: 46038.011 | L19: [16,17,18] | M19: ["A16","中文","emoji-16"] | N19: {"x":16,"y":16.5} | O19: {"x":16,"y":17,"z":18} | P19: {"alpha":16,"row":19} | Q19: 行16 制表符 换行\反斜杠"引号,逗号 | R19: 文本16
A20: 17 | B20: 16 | C20: -29983 | D20: -999983 | E20: 9000000017 | F20: 16000000 | G20: 1.7 | H20: 5.6666667 | I20: FALSE | J20: 170 | K20: 46039.012 | L20: [17,18,19] | M20: ["A17","中文","emoji-17"] | N20: {"x":17,"y":17.5} | O20: {"x":17,"y":18,"z":19} | P20: {"alpha":17,"row":20} | Q20: 行17 制表符 换行\反斜杠"引号,逗号 | R20: 文本17
A21: 18 | B21: 17 | C21: -29982 | D21: -999982 | E21: 9000000018 | F21: 17000000 | G21: 1.8 | H21: 6 | I21: TRUE | J21: 180 | K21: 46040.012 | L21: [18,19,20] | M21: ["A18","中文","emoji-18"] | N21: {"x":18,"y":18.5} | O21: {"x":18,"y":19,"z":20} | P21: {"alpha":18,"row":21} | Q21: 行18 制表符 换行\反斜杠"引号,逗号 | R21: 文本18
A22: 19 | B22: 18 | C22: -29981 | D22: -999981 | E22: 9000000019 | F22: 18000000 | G22: 1.9 | H22: 6.3333333 | I22: FALSE | J22: 190 | K22: 46041.013 | L22: [19,20,21] | M22: ["A19","中文","emoji-19"] | N22: {"x":19,"y":19.5} | O22: {"x":19,"y":20,"z":21} | P22: {"alpha":19,"row":22} | Q22: 行19 制表符 换行\反斜杠"引号,逗号 | R22: 文本19
A23: 20 | B23: 19 | C23: -29980 | D23: -999980 | E23: 9000000020 | F23: 19000000 | G23: 2 | H23: 6.6666667 | I23: TRUE | K23: 46042.014 | L23: [20,21,22] | M23: ["A20","中文","emoji-20"] | N23: {"x":20,"y":20.5} | O23: {"x":20,"y":21,"z":22} | P23: {"alpha":20,"row":23} | Q23: 行20 制表符 换行\反斜杠"引号,逗号 | R23: 文本20
A24: 21 | B24: 20 | C24: -29979 | D24: -999979 | E24: 9000000021 | F24: 20000000 | G24: 2.1 | H24: 7 | I24: FALSE | J24: 210 | K24: 46043.015 | L24: [21,22,23] | M24: ["A21","中文","emoji-21"] | N24: {"x":21,"y":21.5} | O24: {"x":21,"y":22,"z":23} | P24: {"alpha":21,"row":24} | Q24: 行21 制表符 换行\反斜杠"引号,逗号 | R24: 文本21
A25: 22 | B25: 21 | C25: -29978 | D25: -999978 | E25: 9000000022 | F25: 21000000 | G25: 2.2 | H25: 7.3333333 | I25: TRUE | J25: 220 | K25: 46044.015 | L25: [22,23,24] | M25: ["A22","中文","emoji-22"] | N25: {"x":22,"y":22.5} | O25: {"x":22,"y":23,"z":24} | P25: {"alpha":22,"row":25} | Q25: 行22 制表符 换行\反斜杠"引号,逗号 | R25: 文本22
A26: 23 | B26: 22 | C26: -29977 | D26: -999977 | E26: 9000000023 | F26: 22000000 | G26: 2.3 | H26: 7.6666667 | I26: FALSE | J26: 230 | K26: 46045.016 | L26: [23,24,25] | M26: ["A23","中文","emoji-23"] | N26: {"x":23,"y":23.5} | O26: {"x":23,"y":24,"z":25} | P26: {"alpha":23,"row":26} | Q26: 行23 制表符 换行\反斜杠"引号,逗号 | R26: 文本23
A27: 24 | B27: 23 | C27: -29976 | D27: -999976 | E27: 9000000024 | F27: 23000000 | G27: 2.4 | H27: 8 | I27: TRUE | J27: 240 | K27: 46046.017 | L27: [24,25,26] | M27: ["A24","中文","emoji-24"] | N27: {"x":24,"y":24.5} | O27: {"x":24,"y":25,"z":26} | P27: {"alpha":24,"row":27} | Q27: 行24 制表符 换行\反斜杠"引号,逗号 | R27: 文本24
A28: 25 | B28: 24 | C28: -29975 | D28: -999975 | E28: 9000000025 | F28: 24000000 | G28: 2.5 | H28: 8.3333333 | I28: FALSE | J28: 250 | K28: 46047.017 | L28: [25,26,27] | M28: ["A25","中文","emoji-25"] | N28: {"x":25,"y":25.5} | O28: {"x":25,"y":26,"z":27} | P28: {"alpha":25,"row":28} | Q28: 行25 制表符 换行\反斜杠"引号,逗号 | R28: 文本25
A29: 26 | B29: 25 | C29: -29974 | D29: -999974 | E29: 9000000026 | F29: 25000000 | G29: 2.6 | H29: 8.6666667 | I29: TRUE | J29: 260 | K29: 46048.018 | L29: [26,27,28] | M29: ["A26","中文","emoji-26"] | N29: {"x":26,"y":26.5} | O29: {"x":26,"y":27,"z":28} | P29: {"alpha":26,"row":29} | Q29: 行26 制表符 换行\反斜杠"引号,逗号 | R29: 文本26
A30: 27 | B30: 26 | C30: -29973 | D30: -999973 | E30: 9000000027 | F30: 26000000 | G30: 2.7 | H30: 9 | I30: FALSE | J30: 270 | K30: 46049.019 | L30: [27,28,29] | M30: ["A27","中文","emoji-27"] | N30: {"x":27,"y":27.5} | O30: {"x":27,"y":28,"z":29} | P30: {"alpha":27,"row":30} | Q30: 行27 制表符 换行\反斜杠"引号,逗号 | R30: 文本27
A31: 28 | B31: 27 | C31: -29972 | D31: -999972 | E31: 9000000028 | F31: 27000000 | G31: 2.8 | H31: 9.3333333 | I31: TRUE | J31: 280 | K31: 46050.019 | L31: [28,29,30] | M31: ["A28","中文","emoji-28"] | N31: {"x":28,"y":28.5} | O31: {"x":28,"y":29,"z":30} | P31: {"alpha":28,"row":31} | Q31: 行28 制表符 换行\反斜杠"引号,逗号 | R31: 文本28
A32: 29 | B32: 28 | C32: -29971 | D32: -999971 | E32: 9000000029 | F32: 28000000 | G32: 2.9 | H32: 9.6666667 | I32: FALSE | J32: 290 | K32: 46051.02 | L32: [29,30,31] | M32: ["A29","中文","emoji-29"] | N32: {"x":29,"y":29.5} | O32: {"x":29,"y":30,"z":31} | P32: {"alpha":29,"row":32} | Q32: 行29 制表符 换行\反斜杠"引号,逗号 | R32: 文本29
A33: 30 | B33: 29 | C33: -29970 | D33: -999970 | E33: 9000000030 | F33: 29000000 | G33: 3 | H33: 10 | I33: TRUE | K33: 46052.021 | L33: [30,31,32] | M33: ["A30","中文","emoji-30"] | N33: {"x":30,"y":30.5} | O33: {"x":30,"y":31,"z":32} | P33: {"alpha":30,"row":33} | Q33: 行30 制表符 换行\反斜杠"引号,逗号
A34: 31 | B34: 30 | C34: -29969 | D34: -999969 | E34: 9000000031 | F34: 30000000 | G34: 3.1 | H34: 10.333333 | I34: FALSE | J34: 310 | K34: 46053.022 | L34: [31,32,33] | M34: ["A31","中文","emoji-31"] | N34: {"x":31,"y":31.5} | O34: {"x":31,"y":32,"z":33} | P34: {"alpha":31,"row":34} | Q34: 行31 制表符 换行\反斜杠"引号,逗号 | R34: 文本31
A35: 32 | B35: 31 | C35: -29968 | D35: -999968 | E35: 9000000032 | F35: 31000000 | G35: 3.2 | H35: 10.666667 | I35: TRUE | J35: 320 | K35: 46054.022 | L35: [32,33,34] | M35: ["A32","中文","emoji-32"] | N35: {"x":32,"y":32.5} | O35: {"x":32,"y":33,"z":34} | P35: {"alpha":32,"row":35} | Q35: 行32 制表符 换行\反斜杠"引号,逗号 | R35: 文本32
A36: 33 | B36: 32 | C36: -29967 | D36: -999967 | E36: 9000000033 | F36: 32000000 | G36: 3.3 | H36: 11 | I36: FALSE | J36: 330 | K36: 46055.023 | L36: [33,34,35] | M36: ["A33","中文","emoji-33"] | N36: {"x":33,"y":33.5} | O36: {"x":33,"y":34,"z":35} | P36: {"alpha":33,"row":36} | Q36: 行33 制表符 换行\反斜杠"引号,逗号 | R36: 文本33
A37: 34 | B37: 33 | C37: -29966 | D37: -999966 | E37: 9000000034 | F37: 33000000 | G37: 3.4 | H37: 11.333333 | I37: TRUE | J37: 340 | K37: 46056.024 | L37: [34,35,36] | M37: ["A34","中文","emoji-34"] | N37: {"x":34,"y":34.5} | O37: {"x":34,"y":35,"z":36} | P37: {"alpha":34,"row":37} | Q37: 行34 制表符 换行\反斜杠"引号,逗号 | R37: 文本34
A38: 35 | B38: 34 | C38: -29965 | D38: -999965 | E38: 9000000035 | F38: 34000000 | G38: 3.5 | H38: 11.666667 | I38: FALSE | J38: 350 | K38: 46057.024 | L38: [35,36,37] | M38: ["A35","中文","emoji-35"] | N38: {"x":35,"y":35.5} | O38: {"x":35,"y":36,"z":37} | P38: {"alpha":35,"row":38} | Q38: 行35 制表符 换行\反斜杠"引号,逗号 | R38: 文本35
A39: 36 | B39: 35 | C39: -29964 | D39: -999964 | E39: 9000000036 | F39: 35000000 | G39: 3.6 | H39: 12 | I39: TRUE | J39: 360 | K39: 46058.025 | L39: [36,37,38] | M39: ["A36","中文","emoji-36"] | N39: {"x":36,"y":36.5} | O39: {"x":36,"y":37,"z":38} | P39: {"alpha":36,"row":39} | Q39: 行36 制表符 换行\反斜杠"引号,逗号 | R39: 文本36
A40: 37 | B40: 36 | C40: -29963 | D40: -999963 | E40: 9000000037 | F40: 36000000 | G40: 3.7 | H40: 12.333333 | I40: FALSE | J40: 370 | K40: 46059.026 | L40: [37,38,39] | M40: ["A37","中文","emoji-37"] | N40: {"x":37,"y":37.5} | O40: {"x":37,"y":38,"z":39} | P40: {"alpha":37,"row":40} | Q40: 行37 制表符 换行\反斜杠"引号,逗号 | R40: 文本37
...

Sheet FormulaCells
A1: id,key | B1: a | C1: b | D1: sum | E1: product | F1: textFormula | G1: boolFormula | H1: crossSheet
A2: int | B2: double | C2: double | D2: double | E2: double | F2: string | G2: bool | H2: double
A3: key | B3: 输入 A | C3: 输入 B | D3: A+B | E3: A*B | F3: 文本公式 | G3: 布尔公式 | H3: 跨表公式
A4: 100 | B4: 1.26 | C4: 1.27 | D4: =B4+C4 -> 2.53 | E4: =B4*C4 -> 1.6002 | F4: ="row-"&A4 -> row-100 | G4: =B4<C4 -> TRUE | H4: =SingleKey!D4 -> 1.28
A5: 200 | B5: 2.51 | C5: 2.52 | D5: =B5+C5 -> 5.03 | E5: =B5*C5 -> 6.3252 | F5: ="row-"&A5 -> row-200 | G5: =B5<C5 -> TRUE | H5: =SingleKey!D5 -> 2.53
A6: 300 | B6: 3.76 | C6: 3.77 | D6: =B6+C6 -> 7.53 | E6: =B6*C6 -> 14.1752 | F6: ="row-"&A6 -> row-300 | G6: =B6<C6 -> TRUE | H6: =SingleKey!D6 -> 3.78
A7: 400 | B7: 5.01 | C7: 5.02 | D7: =B7+C7 -> 10.03 | E7: =B7*C7 -> 25.1502 | F7: ="row-"&A7 -> row-400 | G7: =B7<C7 -> TRUE | H7: =SingleKey!D7 -> 5.03
A8: 500 | B8: 6.26 | C8: 6.27 | D8: =B8+C8 -> 12.53 | E8: =B8*C8 -> 39.2502 | F8: ="row-"&A8 -> row-500 | G8: =B8<C8 -> TRUE | H8: =SingleKey!D8 -> 6.28
A9: 600 | B9: 7.51 | C9: 7.52 | D9: =B9+C9 -> 15.03 | E9: =B9*C9 -> 56.4752 | F9: ="row-"&A9 -> row-600 | G9: =B9<C9 -> TRUE | H9: =SingleKey!D9 -> 7.53
A10: 700 | B10: 8.76 | C10: 8.77 | D10: =B10+C10 -> 17.53 | E10: =B10*C10 -> 76.8252 | F10: ="row-"&A10 -> row-700 | G10: =B10<C10 -> TRUE | H10: =SingleKey!D10 -> 8.78
A11: 800 | B11: 10.01 | C11: 10.02 | D11: =B11+C11 -> 20.03 | E11: =B11*C11 -> 100.3002 | F11: ="row-"&A11 -> row-800 | G11: =B11<C11 -> TRUE | H11: =SingleKey!D11 -> 10.03
A12: 900 | B12: 11.26 | C12: 11.27 | D12: =B12+C12 -> 22.53 | E12: =B12*C12 -> 126.9002 | F12: ="row-"&A12 -> row-900 | G12: =B12<C12 -> TRUE | H12: =SingleKey!D12 -> 11.28
A13: 1000 | B13: 12.51 | C13: 12.52 | D13: =B13+C13 -> 25.03 | E13: =B13*C13 -> 156.6252 | F13: ="row-"&A13 -> row-1000 | G13: =B13<C13 -> TRUE | H13: =SingleKey!D13 -> 12.53
A14: 1100 | B14: 13.76 | C14: 13.77 | D14: =B14+C14 -> 27.53 | E14: =B14*C14 -> 189.4752 | F14: ="row-"&A14 -> row-1100 | G14: =B14<C14 -> TRUE | H14: =SingleKey!D14 -> 13.78
A15: 1200 | B15: 15.01 | C15: 15.02 | D15: =B15+C15 -> 30.03 | E15: =B15*C15 -> 225.4502 | F15: ="row-"&A15 -> row-1200 | G15: =B15<C15 -> TRUE | H15: =SingleKey!D15 -> 15.03
... A203: 20000 | B203: 250.01 | C203: 250.02 | D203: =B203+C203 -> 500.03 | E203: =B203*C203 -> 62507.5 | F203: ="row-"&A203 -> row-20000 | G203: =B203<C203 -> TRUE | H203: =SingleKey!D203 -> 250.03

Sheet CommentRows
A1: id,key | B1: value | C1: memo
A2: int | B2: string | C2: string
A3: 编号 | B3: 值 | C3: 备注
A4: 100 | B4: 行1_列1_中文_Unicode_😀_comma,quote"_line | C4: 行1_列2_中文_Unicode_😀_comma,quote"_line
A5: 200 | B5: 行2_列1_中文_Unicode_😀_comma,quote"_line | C5: 行2_列2_中文_Unicode_😀_comma,quote"_line
A6: 300 | B6: 行3_列1_中文_Unicode_😀_comma,quote"_line | C6: 行3_列2_中文_Unicode_😀_comma,quote"_line
A7: 400 | B7: 行4_列1_中文_Unicode_😀_comma,quote"_line | C7: 行4_列2_中文_Unicode_😀_comma,quote"_line
A8: 500 | B8: 行5_列1_中文_Unicode_😀_comma,quote"_line | C8: 行5_列2_中文_Unicode_😀_comma,quote"_line
A9: # 这是一整行注释，应该跳过
